Workbook

Sheet Raw data
A1: Sector | B1: Year | C1: Month | D1: Cereals and products | E1: Meat and fish | F1: Egg | G1: Milk and products | H1: Oils and fats | I1: Fruits | J1: Vegetables | K1: Pulses and products | L1: Sugar and Confectionery | M1: Spices | N1: Non-alcoholic beverages | O1: Prepared meals, snacks, sweets etc. | P1: Food and beverages | Q1: Pan, tobacco and intoxicants | R1: Clothing | S1: Footwear | T1: Clothing and footwear | U1: Housing | V1: Fuel and light | W1: Household goods and services | X1: Health | Y1: Transport and communication | Z1: Recreation and amusement | AA1: Education | AB1: Personal care and effects | AC1: Miscellaneous | AD1: General index
A2: Rural | B2: 2013 | C2: January | D2: 107.5 | E2: 106.3 | F2: 108.1 | G2: 104.9 | H2: 106.1 | I2: 103.9 | J2: 101.9 | K2: 106.1 | L2: 106.8 | M2: 103.1 | N2: 104.8 | O2: 106.7 | P2: 105.5 | Q2: 105.1 | R2: 106.5 | S2: 105.8 | T2: 106.4 | U2: NA | V2: 105.5 | W2: 104.8 | X2: 104 | Y2: 103.3 | Z2: 103.4 | AA2: 103.8 | AB2: 104.7 | AC2: 104 | AD2: 105.1
A3: Urban | B3: 2013 | C3: January | D3: 110.5 | E3: 109.1 | F3: 113 | G3: 103.6 | H3: 103.4 | I3: 102.3 | J3: 102.9 | K3: 105.8 | L3: 105.1 | M3: 101.8 | N3: 105.1 | O3: 107.9 | P3: 105.9 | Q3: 105.2 | R3: 105.9 | S3: 105 | T3: 105.8 | U3: 100.3 | V3: 105.4 | W3: 104.8 | X3: 104.1 | Y3: 103.2 | Z3: 102.9 | AA3: 103.5 | AB3: 104.3 | AC3: 103.7 | AD3: 104
A4: Rural+Urban | B4: 2013 | C4: January | D4: 108.4 | E4: 107.3 | F4: 110 | G4: 104.4 | H4: 105.1 | I4: 103.2 | J4: 102.2 | K4: 106 | L4: 106.2 | M4: 102.7 | N4: 104.9 | O4: 107.3 | P4: 105.6 | Q4: 105.1 | R4: 106.3 | S4: 105.5 | T4: 106.2 | U4: 100.3 | V4: 105.5 | W4: 104.8 | X4: 104 | Y4: 103.2 | Z4: 103.1 | AA4: 103.6 | AB4: 104.5 | AC4: 103.9 | AD4: 104.6
A5: Rural | B5: 2013 | C5: February | D5: 109.2 | E5: 108.7 | F5: 110.2 | G5: 105.4 | H5: 106.7 | I5: 104 | J5: 102.4 | K5: 105.9 | L5: 105.7 | M5: 103.1 | N5: 105.1 | O5: 107.7 | P5: 106.3 | Q5: 105.6 | R5: 107.1 | S5: 106.3 | T5: 107 | U5: NA | V5: 106.2 | W5: 105.2 | X5: 104.4 | Y5: 103.9 | Z5: 104 | AA5: 104.1 | AB5: 104.6 | AC5: 104.4 | AD5: 105.8
A6: Urban | B6: 2013 | C6: February | D6: 112.9 | E6: 112.9 | F6: 116.9 | G6: 104 | H6: 103.5 | I6: 103.1 | J6: 104.9 | K6: 104.1 | L6: 103.8 | M6: 102.3 | N6: 106 | O6: 109 | P6: 107.2 | Q6: 106 | R6: 106.6 | S6: 105.5 | T6: 106.4 | U6: 100.4 | V6: 105.7 | W6: 105.2 | X6: 104.7 | Y6: 104.4 | Z6: 103.3 | AA6: 103.7 | AB6: 104.3 | AC6: 104.3 | AD6: 104.7
A7: Rural+Urban | B7: 2013 | C7: February | D7: 110.4 | E7: 110.2 | F7: 112.8 | G7: 104.9 | H7: 105.5 | I7: 103.6 | J7: 103.2 | K7: 105.3 | L7: 105.1 | M7: 102.8 | N7: 105.5 | O7: 108.3 | P7: 106.6 | Q7: 105.7 | R7: 106.9 | S7: 106 | T7: 106.8 | U7: 100.4 | V7: 106 | W7: 105.2 | X7: 104.5 | Y7: 104.2 | Z7: 103.6 | AA7: 103.9 | AB7: 104.5 | AC7: 104.4 | AD7: 105.3
A8: Rural | B8: 2013 | C8: March | D8: 110.2 | E8: 108.8 | F8: 109.9 | G8: 105.6 | H8: 106.2 | I8: 105.7 | J8: 101.4 | K8: 105.7 | L8: 105 | M8: 103.3 | N8: 105.6 | O8: 108.2 | P8: 106.6 | Q8: 106.5 | R8: 107.6 | S8: 106.8 | T8: 107.5 | U8: NA | V8: 106.1 | W8: 105.6 | X8: 104.7 | Y8: 104.6 | Z8: 104 | AA8: 104.3 | AB8: 104.3 | AC8: 104.6 | AD8: 106
A9: Urban | B9: 2013 | C9: March | D9: 113.9 | E9: 111.4 | F9: 113.2 | G9: 104.3 | H9: 102.7 | I9: 104.9 | J9: 103.8 | K9: 103.5 | L9: 102.6 | M9: 102.4 | N9: 107 | O9: 109.8 | P9: 107.3 | Q9: 106.8 | R9: 107.2 | S9: 106 | T9: 107 | U9: 100.4 | V9: 106 | W9: 105.7 | X9: 105.2 | Y9: 105.5 | Z9: 103.5 | AA9: 103.8 | AB9: 104.2 | AC9: 104.9 | AD9: 105
A10: Rural+Urban | B10: 2013 | C10: March | D10: 111.4 | E10: 109.7 | F10: 111.2 | G10: 105.1 | H10: 104.9 | I10: 105.3 | J10: 102.2 | K10: 105 | L10: 104.2 | M10: 103 | N10: 106.2 | O10: 108.9 | P10: 106.9 | Q10: 106.6 | R10: 107.4 | S10: 106.5 | T10: 107.3 | U10: 100.4 | V10: 106.1 | W10: 105.6 | X10: 104.9 | Y10: 105.1 | Z10: 103.7 | AA10: 104 | AB10: 104.3 | AC10: 104.7 | AD10: 105.5
A11: Rural | B11: 2013 | C11: April | D11: 110.2 | E11: 109.5 | F11: 106.9 | G11: 106.3 | H11: 105.7 | I11: 108.3 | J11: 103.4 | K11: 105.7 | L11: 104.2 | M11: 103.2 | N11: 106.5 | O11: 108.8 | P11: 107.1 | Q11: 107.1 | R11: 108.1 | S11: 107.4 | T11: 108 | U11: NA | V11: 106.5 | W11: 106.1 | X11: 105.1 | Y11: 104.4 | Z11: 104.5 | AA11: 104.8 | AB11: 102.7 | AC11: 104.6 | AD11: 106.4
A12: Urban | B12: 2013 | C12: April | D12: 114.6 | E12: 113.4 | F12: 106 | G12: 104.7 | H12: 102.1 | I12: 109.5 | J12: 109.7 | K12: 104.6 | L12: 102 | M12: 103.5 | N12: 108.2 | O12: 110.6 | P12: 108.8 | Q12: 108.5 | R12: 107.9 | S12: 106.4 | T12: 107.7 | U12: 100.5 | V12: 106.4 | W12: 106.5 | X12: 105.7 | Y12: 105 | Z12: 104 | AA12: 105.2 | AB12: 103.2 | AC12: 105.1 | AD12: 105.7
A13: Rural+Urban | B13: 2013 | C13: April | D13: 111.6 | E13: 110.9 | F13: 106.6 | G13: 105.7 | H13: 104.4 | I13: 108.9 | J13: 105.5 | K13: 105.3 | L13: 103.5 | M13: 103.3 | N13: 107.2 | O13: 109.6 | P13: 107.7 | Q13: 107.5 | R13: 108 | S13: 107 | T13: 107.9 | U13: 100.5 | V13: 106.5 | W13: 106.3 | X13: 105.3 | Y13: 104.7 | Z13: 104.2 | AA13: 105 | AB13: 102.9 | AC13: 104.8 | AD13: 106.1
A14: Rural | B14: 2013 | C14: May | D14: 110.9 | E14: 109.8 | F14: 105.9 | G14: 107.5 | H14: 105.3 | I14: 108.1 | J14: 107.3 | K14: 106.1 | L14: 103.7 | M14: 104 | N14: 107.4 | O14: 109.9 | P14: 108.1 | Q14: 108.1 | R14: 108.8 | S14: 107.9 | T14: 108.6 | U14: NA | V14: 107.5 | W14: 106.8 | X14: 105.7 | Y14: 104.1 | Z14: 105 | AA14: 105.5 | AB14: 102.1 | AC14: 104.8 | AD14: 107.2
A15: Urban | B15: 2013 | C15: May | D15: 115.4 | E15: 114.2 | F15: 102.7 | G15: 105.5 | H15: 101.5 | I15: 110.6 | J15: 123.7 | K15: 105.2 | L15: 101.9 | M15: 105 | N15: 109.1 | O15: 111.3 | P15: 111.1 | Q15: 109.8 | R15: 108.5 | S15: 106.7 | T15: 108.3 | U15: 100.5 | V15: 107.2 | W15: 107.1 | X15: 106.2 | Y15: 103.9 | Z15: 104.6 | AA15: 105.7 | AB15: 102.6 | AC15: 104.9 | AD15: 106.6
A16: Rural+Urban | B16: 2013 | C16: May | D16: 112.3 | E16: 111.3 | F16: 104.7 | G16: 106.8 | H16: 103.9 | I16: 109.3 | J16: 112.9 | K16: 105.8 | L16: 103.1 | M16: 104.3 | N16: 108.1 | O16: 110.5 | P16: 109.2 | Q16: 108.6 | R16: 108.7 | S16: 107.4 | T16: 108.5 | U16: 100.5 | V16: 107.4 | W16: 106.9 | X16: 105.9 | Y16: 104 | Z16: 104.8 | AA16: 105.6 | AB16: 102.3 | AC16: 104.8 | AD16: 106.9
A17: Rural | B17: 2013 | C17: June | D17: 112.3 | E17: 112.1 | F17: 108.1 | G17: 108.3 | H17: 105.9 | I17: 109.2 | J17: 118 | K17: 106.8 | L17: 104.1 | M17: 105.4 | N17: 108.2 | O17: 111 | P17: 110.6 | Q17: 109 | R17: 109.7 | S17: 108.8 | T17: 109.5 | U17: NA | V17: 108.5 | W17: 107.5 | X17: 106.3 | Y17: 105 | Z17: 105.6 | AA17: 106.5 | AB17: 102.5 | AC17: 105.5 | AD17: 108.9
A18: Urban | B18: 2013 | C18: June | D18: 117 | E18: 120.1 | F18: 112.5 | G18: 107.3 | H18: 101.3 | I18: 112.4 | J18: 143.6 | K18: 105.4 | L18: 101.4 | M18: 106.4 | N18: 110 | O18: 112.2 | P18: 115 | Q18: 110.9 | R18: 109.2 | S18: 107.2 | T18: 108.9 | U18: 106.6 | V18: 108 | W18: 107.7 | X18: 106.5 | Y18: 105.2 | Z18: 105.2 | AA18: 108.1 | AB18: 103.3 | AC18: 106.1 | AD18: 109.7
A19: Rural+Urban | B19: 2013 | C19: June | D19: 113.8 | E19: 114.9 | F19: 109.8 | G19: 107.9 | H19: 104.2 | I19: 110.7 | J19: 126.7 | K19: 106.3 | L19: 103.2 | M19: 105.7 | N19: 109 | O19: 111.6 | P19: 112.2 | Q19: 109.5 | R19: 109.5 | S19: 108.1 | T19: 109.3 | U19: 106.6 | V19: 108.3 | W19: 107.6 | X19: 106.4 | Y19: 105.1 | Z19: 105.4 | AA19: 107.4 | AB19: 102.8 | AC19: 105.8 | AD19: 109.3
A20: Rural | B20: 2013 | C20: July | D20: 113.4 | E20: 114.9 | F20: 110.5 | G20: 109.3 | H20: 106.2 | I20: 110.3 | J20: 129.2 | K20: 107.1 | L20: 104.3 | M20: 106.4 | N20: 109.1 | O20: 112.1 | P20: 113.1 | Q20: 109.8 | R20: 110.5 | S20: 109.5 | T20: 110.3 | U20: NA | V20: 109.5 | W20: 108.3 | X20: 106.9 | Y20: 106.8 | Z20: 106.4 | AA20: 107.8 | AB20: 102.5 | AC20: 106.5 | AD20: 110.7
A21: Urban | B21: 2013 | C21: July | D21: 117.8 | E21: 119.2 | F21: 114 | G21: 108.3 | H21: 101.1 | I21: 113.2 | J21: 160.9 | K21: 105.1 | L21: 101.3 | M21: 107.5 | N21: 110.4 | O21: 113.1 | P21: 117.5 | Q21: 111.7 | R21: 109.8 | S21: 107.8 | T21: 109.5 | U21: 107.7 | V21: 108.6 | W21: 108.1 | X21: 107.1 | Y21: 107.3 | Z21: 105.9 | AA21: 110.1 | AB21: 103.2 | AC21: 107.3 | AD21: 111.4
A22: Rural+Urban | B22: 2013 | C22: July | D22: 114.8 | E22: 116.4 | F22: 111.9 | G22: 108.9 | H22: 104.3 | I22: 111.7 | J22: 140 | K22: 106.4 | L22: 103.3 | M22: 106.8 | N22: 109.6 | O22: 112.6 | P22: 114.7 | Q22: 110.3 | R22: 110.2 | S22: 108.8 | T22: 110 | U22: 107.7 | V22: 109.2 | W22: 108.2 | X22: 107 | Y22: 107.1 | Z22: 106.1 | AA22: 109.1 | AB22: 102.8 | AC22: 106.9 | AD22: 111
A23: Rural | B23: 2013 | C23: August | D23: 114.3 | E23: 115.4 | F23: 111.1 | G23: 110 | H23: 106.4 | I23: 110.8 | J23: 138.9 | K23: 107.4 | L23: 104.1 | M23: 106.9 | N23: 109.7 | O23: 112.6 | P23: 114.9 | Q23: 110.7 | R23: 111.3 | S23: 110.2 | T23: 111.1 | U23: NA | V23: 109.9 | W23: 108.7 | X23: 107.5 | Y23: 107.8 | Z23: 106.8 | AA23: 108.7 | AB23: 105 | AC23: 107.5 | AD23: 112.1
A24: Urban | B24: 2013 | C24: August | D24: 118.3 | E24: 120.4 | F24: 112.7 | G24: 108.9 | H24: 101.1 | I24: 108.7 | J24: 177 | K24: 104.7 | L24: 101 | M24: 108.5 | N24: 110.9 | O24: 114.3 | P24: 119.6 | Q24: 112.4 | R24: 110.6 | S24: 108.3 | T24: 110.2 | U24: 108.9 | V24: 109.3 | W24: 108.7 | X24: 107.6 | Y24: 108.1 | Z24: 106.5 | AA24: 110.8 | AB24: 106 | AC24: 108.3 | AD24: 112.7
A25: Rural+Urban | B25: 2013 | C25: August | D25: 115.6 | E25: 117.2 | F25: 111.7 | G25: 109.6 | H25: 104.5 | I25: 109.8 | J25: 151.8 | K25: 106.5 | L25: 103.1 | M25: 107.4 | N25: 110.2 | O25: 113.4 | P25: 116.6 | Q25: 111.2 | R25: 111 | S25: 109.4 | T25: 110.7 | U25: 108.9 | V25: 109.7 | W25: 108.7 | X25: 107.5 | Y25: 108 | Z25: 106.6 | AA25: 109.9 | AB25: 105.4 | AC25: 107.9 | AD25: 112.4
A26: Rural | B26: 2013 | C26: September | D26: 115.4 | E26: 115.7 | F26: 111.7 | G26: 111 | H26: 107.4 | I26: 110.9 | J26: 154 | K26: 108.1 | L26: 104.2 | M26: 107.9 | N26: 110.4 | O26: 114 | P26: 117.8 | Q26: 111.7 | R26: 112.7 | S26: 111.4 | T26: 112.5 | U26: NA | V26: 111.1 | W26: 109.6 | X26: 108.3 | Y26: 109.3 | Z26: 107.7 | AA26: 109.8 | AB26: 106.7 | AC26: 108.7 | AD26: 114.2
A27: Urban | B27: 2013 | C27: September | D27: 118.6 | E27: 119.1 | F27: 113.2 | G27: 109.6 | H27: 101.7 | I27: 103.2 | J27: 174.3 | K27: 105.1 | L27: 100.8 | M27: 109.1 | N27: 111.1 | O27: 115.4 | P27: 119.2 | Q27: 112.9 | R27: 111.4 | S27: 109 | T27: 111.1 | U27: 109.7 | V27: 109.5 | W27: 109.6 | X27: 107.9 | Y27: 110.4 | Z27: 107.4 | AA27: 111.2 | AB27: 106.9 | AC27: 109.4 | AD27: 113.2
A28: Rural+Urban | B28: 2013 | C28: September | D28: 116.4 | E28: 116.9 | F28: 112.3 | G28: 110.5 | H28: 105.3 | I28: 107.3 | J28: 160.9 | K28: 107.1 | L28: 103.1 | M28: 108.3 | N28: 110.7 | O28: 114.6 | P28: 118.3 | Q28: 112 | R28: 112.2 | S28: 110.4 | T28: 111.9 | U28: 109.7 | V28: 110.5 | W28: 109.6 | X28: 108.1 | Y28: 109.9 | Z28: 107.5 | AA28: 110.6 | AB28: 106.8 | AC28: 109 | AD28: 113.7
A29: Rural | B29: 2013 | C29: October | D29: 116.3 | E29: 115.4 | F29: 112.6 | G29: 111.7 | H29: 107.7 | I29: 113.2 | J29: 164.9 | K29: 108.3 | L29: 103.9 | M29: 108.2 | N29: 111.1 | O29: 114.9 | P29: 119.8 | Q29: 112.2 | R29: 113.6 | S29: 112.3 | T29: 113.4 | U29: NA | V29: 111.6 | W29: 110.4 | X29: 108.9 | Y29: 109.3 | Z29: 108.3 | AA29: 110.2 | AB29: 107.5 | AC29: 109.1 | AD29: 115.5
A30: Urban | B30: 2013 | C30: October | D30: 118.9 | E30: 118.1 | F30: 114.5 | G30: 110.4 | H30: 102.3 | I30: 106.2 | J30: 183.5 | K30: 105.3 | L30: 100.2 | M30: 109.6 | N30: 111.4 | O30: 116 | P30: 120.8 | Q30: 113.5 | R30: 112.5 | S30: 109.7 | T30: 112 | U30: 110.5 | V30: 109.7 | W30: 110.2 | X30: 108.2 | Y30: 109.7 | Z30: 108 | AA30: 111.3 | AB30: 107.3 | AC30: 109.4 | AD30: 114
A31: Rural+Urban | B31: 2013 | C31: October | D31: 117.1 | E31: 116.3 | F31: 113.3 | G31: 111.2 | H31: 105.7 | I31: 109.9 | J31: 171.2 | K31: 107.3 | L31: 102.7 | M31: 108.7 | N31: 111.2 | O31: 115.4 | P31: 120.2 | Q31: 112.5 | R31: 113.2 | S31: 111.2 | T31: 112.8 | U31: 110.5 | V31: 110.9 | W31: 110.3 | X31: 108.6 | Y31: 109.5 | Z31: 108.1 | AA31: 110.8 | AB31: 107.4 | AC31: 109.2 | AD31: 114.8
A32: Rural | B32: 2013 | C32: November | D32: 117.3 | E32: 114.9 | F32: 116.2 | G32: 112.8 | H32: 108.9 | I32: 116.6 | J32: 178.1 | K32: 109.1 | L32: 103.6 | M32: 109 | N32: 111.8 | O32: 116 | P32: 122.5 | Q32: 112.8 | R32: 114.6 | S32: 113.1 | T32: 114.4 | U32: NA | V32: 112.6 | W32: 111.3 | X32: 109.7 | Y32: 109.6 | Z32: 108.7 | AA32: 111 | AB32: 108.2 | AC32: 109.8 | AD32: 117.4
A33: Urban | B33: 2013 | C33: November | D33: 119.8 | E33: 116.3 | F33: 122.6 | G33: 112 | H33: 103.2 | I33: 110 | J33: 192.8 | K33: 106.3 | L33: 99.5 | M33: 110.3 | N33: 111.8 | O33: 117.1 | P33: 122.9 | Q33: 114.1 | R33: 113.5 | S33: 110.3 | T33: 113 | U33: 111.1 | V33: 110 | W33: 110.9 | X33: 108.6 | Y33: 109.5 | Z33: 108.5 | AA33: 111.3 | AB33: 107.9 | AC33: 109.6 | AD33: 115
A34: Rural+Urban | B34: 2013 | C34: November | D34: 118.1 | E34: 115.4 | F34: 118.7 | G34: 112.5 | H34: 106.8 | I34: 113.5 | J34: 183.1 | K34: 108.2 | L34: 102.2 | M34: 109.4 | N34: 111.8 | O34: 116.5 | P34: 122.6 | Q34: 113.1 | R34: 114.2 | S34: 111.9 | T34: 113.8 | U34: 111.1 | V34: 111.6 | W34: 111.1 | X34: 109.3 | Y34: 109.5 | Z34: 108.6 | AA34: 111.2 | AB34: 108.1 | AC34: 109.7 | AD34: 116.3
A35: Rural | B35: 2013 | C35: December | D35: 118.4 | E35: 115.9 | F35: 120.4 | G35: 113.8 | H35: 109.5 | I35: 115.5 | J35: 145.7 | K35: 109.5 | L35: 102.9 | M35: 109.8 | N35: 112.1 | O35: 116.8 | P35: 118.7 | Q35: 113.6 | R35: 115.8 | S35: 114 | T35: 115.5 | U35: NA | V35: 112.8 | W35: 112.1 | X35: 110.1 | Y35: 109.9 | Z35: 109.2 | AA35: 111.6 | AB35: 108.1 | AC35: 110.1 | AD35: 115.5
A36: Urban | B36: 2013 | C36: December | D36: 120.5 | E36: 118.1 | F36: 128.5 | G36: 112.8 | H36: 103.4 | I36: 110.7 | J36: 144.8 | K36: 107.1 | L36: 98.6 | M36: 111.9 | N36: 112.1 | O36: 118.1 | P36: 117.8 | Q36: 115 | R36: 114.2 | S36: 110.9 | T36: 113.7 | U36: 110.7 | V36: 110.4 | W36: 111.3 | X36: 109 | Y36: 109.7 | Z36: 108.9 | AA36: 111.4 | AB36: 107.7 | AC36: 109.8 | AD36: 113.3
A37: Rural+Urban | B37: 2013 | C37: December | D37: 119.1 | E37: 116.7 | F37: 123.5 | G37: 113.4 | H37: 107.3 | I37: 113.3 | J37: 145.4 | K37: 108.7 | L37: 101.5 | M37: 110.5 | N37: 112.1 | O37: 117.4 | P37: 118.4 | Q37: 114 | R37: 115.2 | S37: 112.7 | T37: 114.8 | U37: 110.7 | V37: 111.9 | W37: 111.7 | X37: 109.7 | Y37: 109.8 | Z37: 109 | AA37: 111.5 | AB37: 107.9 | AC37: 110 | AD37: 114.5
A38: Rural | B38: 2014 | C38: January | D38: 118.9 | E38: 117.1 | F38: 120.5 | G38: 114.4 | H38: 109 | I38: 115.5 | J38: 123.9 | K38: 109.6 | L38: 101.8 | M38: 110.2 | N38: 112.4 | O38: 117.3 | P38: 116 | Q38: 114 | R38: 116.5 | S38: 114.5 | T38: 116.2 | U38: NA | V38: 113 | W38: 112.6 | X38: 110.6 | Y38: 110.5 | Z38: 109.6 | AA38: 111.8 | AB38: 108.3 | AC38: 110.6 | AD38: 114.2
A39: Urban | B39: 2014 | C39: January | D39: 121.2 | E39: 122 | F39: 129.9 | G39: 113.6 | H39: 102.9 | I39: 112.1 | J39: 118.9 | K39: 107.5 | L39: 96.9 | M39: 112.7 | N39: 112.1 | O39: 119 | P39: 115.5 | Q39: 115.7 | R39: 114.8 | S39: 111.3 | T39: 114.3 | U39: 111.6 | V39: 111 | W39: 111.9 | X39: 109.7 | Y39: 110.8 | Z39: 109.8 | AA39: 111.5 | AB39: 108 | AC39: 110.5 | AD39: 112.9
A40: Rural+Urban | B40: 2014 | C40: January | D40: 119.6 | E40: 118.8 | F40: 124.1 | G40: 114.1 | H40: 106.8 | I40: 113.9 | J40: 122.2 | K40: 108.9 | L40: 100.2 | M40: 111 | N40: 112.3 | O40: 118.1 | P40: 115.8 | Q40: 114.5 | R40: 115.8 | S40: 113.2 | T40: 115.4 | U40: 111.6 | V40: 112.2 | W40: 112.3 | X40: 110.3 | Y40: 110.7 | Z40: 109.7 | AA40: 111.6 | AB40: 108.2 | AC40: 110.6 | AD40: 113.6
...

Sheet Data cleaning
A1: Sector | B1: Year | C1: Month | D1: Cereals and products | E1: Meat and fish | F1: Egg | G1: Milk and products | H1: Oils and fats | I1: Fruits | J1: Vegetables | K1: Pulses and products | L1: Sugar and Confectionery | M1: Spices | N1: Non-alcoholic beverages | O1: Prepared meals, snacks, sweets etc. | P1: Food and beverages | Q1: Pan, tobacco and intoxicants | R1: Clothing | S1: Footwear | T1: Clothing and footwear | U1: Housing | V1: Fuel and light | W1: Household goods and services | X1: Health | Y1: Transport and communication | Z1: Recreation and amusement | AA1: Education | AB1: Personal care and effects | AC1: Miscellaneous | AD1: General index
A2: Rural | B2: 2013 | C2: January | D2: 107.5 | E2: 106.3 | F2: 108.1 | G2: 104.9 | H2: 106.1 | I2: 103.9 | J2: 101.9 | K2: 106.1 | L2: 106.8 | M2: 103.1 | N2: 104.8 | O2: 106.7 | P2: 105.5 | Q2: 105.1 | R2: 106.5 | S2: 105.8 | T2: 106.4 | U2: 100.3 | V2: 105.5 | W2: 104.8 | X2: 104 | Y2: 103.3 | Z2: 103.4 | AA2: 103.8 | AB2: 104.7 | AC2: 104 | AD2: 105.1
A3: Urban | B3: 2013 | C3: January | D3: 110.5 | E3: 109.1 | F3: 113 | G3: 103.6 | H3: 103.4 | I3: 102.3 | J3: 102.9 | K3: 105.8 | L3: 105.1 | M3: 101.8 | N3: 105.1 | O3: 107.9 | P3: 105.9 | Q3: 105.2 | R3: 105.9 | S3: 105 | T3: 105.8 | U3: 100.4 | V3: 105.4 | W3: 104.8 | X3: 104.1 | Y3: 103.2 | Z3: 102.9 | AA3: 103.5 | AB3: 104.3 | AC3: 103.7 | AD3: 104
A4: Rural+Urban | B4: 2013 | C4: January | D4: 108.4 | E4: 107.3 | F4: 110 | G4: 104.4 | H4: 105.1 | I4: 103.2 | J4: 102.2 | K4: 106 | L4: 106.2 | M4: 102.7 | N4: 104.9 | O4: 107.3 | P4: 105.6 | Q4: 105.1 | R4: 106.3 | S4: 105.5 | T4: 106.2 | U4: 100.4 | V4: 105.5 | W4: 104.8 | X4: 104 | Y4: 103.2 | Z4: 103.1 | AA4: 103.6 | AB4: 104.5 | AC4: 103.9 | AD4: 104.6
A5: Rural | B5: 2013 | C5: February | D5: 109.2 | E5: 108.7 | F5: 110.2 | G5: 105.4 | H5: 106.7 | I5: 104 | J5: 102.4 | K5: 105.9 | L5: 105.7 | M5: 103.1 | N5: 105.1 | O5: 107.7 | P5: 106.3 | Q5: 105.6 | R5: 107.1 | S5: 106.3 | T5: 107 | U5: 100.4 | V5: 106.2 | W5: 105.2 | X5: 104.4 | Y5: 103.9 | Z5: 104 | AA5: 104.1 | AB5: 104.6 | AC5: 104.4 | AD5: 105.8
A6: Urban | B6: 2013 | C6: February | D6: 112.9 | E6: 112.9 | F6: 116.9 | G6: 104 | H6: 103.5 | I6: 103.1 | J6: 104.9 | K6: 104.1 | L6: 103.8 | M6: 102.3 | N6: 106 | O6: 109 | P6: 107.2 | Q6: 106 | R6: 106.6 | S6: 105.5 | T6: 106.4 | U6: 100.5 | V6: 105.7 | W6: 105.2 | X6: 104.7 | Y6: 104.4 | Z6: 103.3 | AA6: 103.7 | AB6: 104.3 | AC6: 104.3 | AD6: 104.7
A7: Rural+Urban | B7: 2013 | C7: February | D7: 110.4 | E7: 110.2 | F7: 112.8 | G7: 104.9 | H7: 105.5 | I7: 103.6 | J7: 103.2 | K7: 105.3 | L7: 105.1 | M7: 102.8 | N7: 105.5 | O7: 108.3 | P7: 106.6 | Q7: 105.7 | R7: 106.9 | S7: 106 | T7: 106.8 | U7: 106.6 | V7: 106 | W7: 105.2 | X7: 104.5 | Y7: 104.2 | Z7: 103.6 | AA7: 103.9 | AB7: 104.5 | AC7: 104.4 | AD7: 105.3
A8: Rural | B8: 2013 | C8: March | D8: 110.2 | E8: 108.8 | F8: 109.9 | G8: 105.6 | H8: 106.2 | I8: 105.7 | J8: 101.4 | K8: 105.7 | L8: 105 | M8: 103.3 | N8: 105.6 | O8: 108.2 | P8: 106.6 | Q8: 106.5 | R8: 107.6 | S8: 106.8 | T8: 107.5 | U8: 100.4 | V8: 106.1 | W8: 105.6 | X8: 104.7 | Y8: 104.6 | Z8: 104 | AA8: 104.3 | AB8: 104.3 | AC8: 104.6 | AD8: 106
A9: Urban | B9: 2013 | C9: March | D9: 113.9 | E9: 111.4 | F9: 113.2 | G9: 104.3 | H9: 102.7 | I9: 104.9 | J9: 103.8 | K9: 103.5 | L9: 102.6 | M9: 102.4 | N9: 107 | O9: 109.8 | P9: 107.3 | Q9: 106.8 | R9: 107.2 | S9: 106 | T9: 107 | U9: 108.9 | V9: 106 | W9: 105.7 | X9: 105.2 | Y9: 105.5 | Z9: 103.5 | AA9: 103.8 | AB9: 104.2 | AC9: 104.9 | AD9: 105
A10: Rural+Urban | B10: 2013 | C10: March | D10: 111.4 | E10: 109.7 | F10: 111.2 | G10: 105.1 | H10: 104.9 | I10: 105.3 | J10: 102.2 | K10: 105 | L10: 104.2 | M10: 103 | N10: 106.2 | O10: 108.9 | P10: 106.9 | Q10: 106.6 | R10: 107.4 | S10: 106.5 | T10: 107.3 | U10: 109.7 | V10: 106.1 | W10: 105.6 | X10: 104.9 | Y10: 105.1 | Z10: 103.7 | AA10: 104 | AB10: 104.3 | AC10: 104.7 | AD10: 105.5
A11: Rural | B11: 2013 | C11: April | D11: 110.2 | E11: 109.5 | F11: 106.9 | G11: 106.3 | H11: 105.7 | I11: 108.3 | J11: 103.4 | K11: 105.7 | L11: 104.2 | M11: 103.2 | N11: 106.5 | O11: 108.8 | P11: 107.1 | Q11: 107.1 | R11: 108.1 | S11: 107.4 | T11: 108 | U11: 100.5 | V11: 106.5 | W11: 106.1 | X11: 105.1 | Y11: 104.4 | Z11: 104.5 | AA11: 104.8 | AB11: 102.7 | AC11: 104.6 | AD11: 106.4
A12: Urban | B12: 2013 | C12: April | D12: 114.6 | E12: 113.4 | F12: 106 | G12: 104.7 | H12: 102.1 | I12: 109.5 | J12: 109.7 | K12: 104.6 | L12: 102 | M12: 103.5 | N12: 108.2 | O12: 110.6 | P12: 108.8 | Q12: 108.5 | R12: 107.9 | S12: 106.4 | T12: 107.7 | U12: 100.5 | V12: 106.4 | W12: 106.5 | X12: 105.7 | Y12: 105 | Z12: 104 | AA12: 105.2 | AB12: 103.2 | AC12: 105.1 | AD12: 105.7
A13: Rural+Urban | B13: 2013 | C13: April | D13: 111.6 | E13: 110.9 | F13: 106.6 | G13: 105.7 | H13: 104.4 | I13: 108.9 | J13: 105.5 | K13: 105.3 | L13: 103.5 | M13: 103.3 | N13: 107.2 | O13: 109.6 | P13: 107.7 | Q13: 107.5 | R13: 108 | S13: 107 | T13: 107.9 | U13: 100.5 | V13: 106.5 | W13: 106.3 | X13: 105.3 | Y13: 104.7 | Z13: 104.2 | AA13: 105 | AB13: 102.9 | AC13: 104.8 | AD13: 106.1
... A259: Rural+Urban | B259: 2020 | C259: March | D259: 145.1 | E259: 167 | F259: 148.1 | G259: 151.5 | H259: 131.2 | I259: 142.5 | J259: 157.3 | K259: 141.1 | L259: 113.2 | M259: 153.2 | N259: 136.7 | O259: 159.6 | P259: 148.9 | Q259: 171.2 | R259: 151.2 | S259: 141.9 | T259: 149.8 | U259: 154.5 | V259: 148.9 | W259: 146.4 | X259: 152.3 | Y259: 129.9 | Z259: 143.7 | AA259: 156.1 | AB259: 145.2 | AC259: 143.8 | AD259: 148.6
A260: Rural | B260: 2020 | C260: April | D260: 147.2 | E260: =AVERAGE(E251,E254,E257) -> 167.2 | F260: 146.9 | G260: 155.6 | H260: 137.1 | I260: 147.3 | J260: 162.7 | K260: 150.2 | L260: 119.8 | M260: 158.7 | N260: 139.2 | O260: =AVERAGE(O251,O254,O257) -> 159.3 | P260: 150.1 | Q260: =AVERAGE(Q251,Q254,Q257) -> 169.5 | R260: =AVERAGE(R251,R254,R257) -> 153.06667 | S260: =AVERAGE(S251,S254,S257) -> 147.5 | T260: =AVERAGE(T251,T254,T257) -> 152.3 | U260: 155.6 | V260: 148.4 | W260: =AVERAGE(W251,W254,W257) -> 151.66667 | X260: 154.3 | Y260: =AVERAGE(Y251,Y254,Y257) -> 136.03333 | Z260: =AVERAGE(Z251,Z254,Z257) -> 150.56667 | AA260: =AVERAGE(AA251,AA254,AA257) -> 161.6 | AB260: =AVERAGE(AB251,AB254,AB257) -> 143.66667 | AC260: =AVERAGE(AC251,AC254,AC257) -> 148.36667 | AD260: =AVERAGE(AD251,AD254,AD257) -> 150.7
A261: Urban | B261: 2020 | C261: April | D261: 151.8 | E261: =AVERAGE(E252,E255,E258) -> 167.56667 | F261: 151.9 | G261: 155.5 | H261: 131.6 | I261: 152.9 | J261: 180 | K261: 150.8 | L261: 121.2 | M261: 154 | N261: 133.5 | O261: =AVERAGE(O252,O255,O258) -> 158.86667 | P261: 153.5 | Q261: =AVERAGE(P252,P255,P258) -> 152.06667 | R261: =AVERAGE(R252,R255,R258) -> 147.33333 | S261: =AVERAGE(S252,S255,S258) -> 133.5 | T261: =AVERAGE(T252,T255,T258) -> 145.23333 | U261: 155.6 | V261: 137.1 | W261: =AVERAGE(W252,W255,W258) -> 140.43333 | X261: 144.8 | Y261: =AVERAGE(Y252,Y255,Y258) -> 125.3 | Z261: =AVERAGE(Z252,Z255,Z258) -> 137.6 | AA261: =AVERAGE(AA252,AA255,AA258) -> 152.26667 | AB261: =AVERAGE(AB252,AB255,AB258) -> 143.63333 | AC261: =AVERAGE(AC252,AC255,AC258) -> 138.5 | AD261: =AVERAGE(AD252,AD255,AD258) -> 147.73333
A262: Rural+Urban | B262: 2020 | C262: April | D262: 148.7 | E262: =AVERAGE(E253,E256,E259) -> 167.3 | F262: 148.8 | G262: 155.6 | H262: 135.1 | I262: 149.9 | J262: 168.6 | K262: 150.4 | L262: 120.3 | M262: 157.1 | N262: 136.8 | O262: =AVERAGE(O253,O256,O259) -> 159.1 | P262: 151.4 | Q262: =AVERAGE(Q253,Q256,Q259) -> 170.16667 | R262: =AVERAGE(R253,R256,R259) -> 150.83333 | S262: =AVERAGE(S253,S256,S259) -> 141.7 | T262: =AVERAGE(T253,T256,T259) -> 149.5 | U262: 155.6 | V262: 144.1 | W262: =AVERAGE(W253,W256,W259) -> 146.33333 | X262: 150.7 | Y262: =AVERAGE(Y253,Y256,Y259) -> 130.36667 | Z262: =AVERAGE(Z253,Z256,Z259) -> 143.23333 | AA262: =AVERAGE(AA253,AA256,AA259) -> 156.13333 | AB262: =AVERAGE(AB253,AB256,AB259) -> 143.63333 | AC262: =AVERAGE(AC253,AC256,AC259) -> 143.6 | AD262: =AVERAGE(AD253,AD256,AD259) -> 149.3
A263: Rural | B263: 2020 | C263: May | D263: =AVERAGE(D251,D254,D257,D260) -> 144.875 | E263: =AVERAGE(E251,E254,E257,E260) -> 167.2 | F263: =AVERAGE(F251,F254,F257,F260) -> 149.725 | G263: =AVERAGE(G251,G254,G257,G260) -> 152.175 | H263: =AVERAGE(H251,H254,H257,H260) -> 134.025 | I263: =AVERAGE(I251,I254,I257,I260) -> 143 | J263: =AVERAGE(J251,J254,J257,J260) -> 167.9 | K263: =AVERAGE(K251,K255,K258,K261) -> 142.8 | L263: =AVERAGE(L251,L254,L257,L260) -> 114.825 | M263: =AVERAGE(M251,M254,M257,M260) -> 154.275 | N263: =AVERAGE(N251,N254,N257,N260) -> 139.775 | O263: =AVERAGE(O251,O254,O257,O260) -> 159.3 | P263: =AVERAGE(P251,P254,P257,P260) -> 150.275 | Q263: =AVERAGE(Q251,Q254,Q257,Q260) -> 169.5 | R263: =AVERAGE(R251,R254,R257,R260) -> 153.06667 | S263: =AVERAGE(S251,S254,S257,S260) -> 147.5 | T263: =AVERAGE(T251,T254,T257,T260) -> 152.3 | U263: 154.7 | V263: =AVERAGE(V251,V254,V257,V260) -> 151.125 | W263: =AVERAGE(W251,W254,W257,W260) -> 151.66667 | X263: =AVERAGE(X251,X254,X257,X260) -> 155.725 | Y263: =AVERAGE(Y251,Y254,Y257,Y260) -> 136.03333 | Z263: =AVERAGE(Z251,Z254,Z257,Z260) -> 150.56667 | AA263: =AVERAGE(AA251,AA254,AA257,AA260) -> 161.6 | AB263: =AVERAGE(AB251,AB254,AB257,AB260) -> 143.66667 | AC263: =AVERAGE(AC251,AC254,AC257,AC260) -> 148.36667 | AD263: =AVERAGE(AD251,AD254,AD257,AD260) -> 150.7
A264: Urban | B264: 2020 | C264: May | D264: =AVERAGE(D252,D255,D258,D261) -> 147.525 | E264: =AVERAGE(E252,E255,E258,E261) -> 167.56667 | F264: =AVERAGE(F252,F255,F258,F261) -> 152.725 | G264: =AVERAGE(G252,G255,G258,G261) -> 151.65 | H264: =AVERAGE(H252,H255,H258,H261) -> 128.2 | I264: =AVERAGE(I252,I255,I258,I261) -> 145.925 | J264: =AVERAGE(J252,J255,J258,J261) -> 184.125 | K264: =AVERAGE(K252,K255,K258,K261) -> 142.3 | ... AD264: =AVERAGE(AD252,AD255,AD258,AD261) -> 147.73333
A265: Rural+Urban | B265: 2020 | C265: May | D265: =AVERAGE(D253,D256,D259,D262) -> 145.725 | E265: =AVERAGE(E253,E256,E259,E262) -> 167.3 | F265: =AVERAGE(F253,F256,F259,F262) -> 150.9 | G265: =AVERAGE(G253,G256,G259,G262) -> 152 | H265: =AVERAGE(H253,H256,H259,H262) -> 131.9 | I265: =AVERAGE(I253,I256,I259,I262) -> 144.35 | J265: =AVERAGE(J253,J256,J259,J262) -> 173.4 | K265: =AVERAGE(K253,K256,K259,K262) -> 143.25 | ... AD265: =AVERAGE(AD253,AD256,AD259,AD262) -> 149.3
A266: Rural | B266: 2020 | C266: June | D266: 148.2 | E266: 190.3 | F266: 149.4 | G266: 153.3 | H266: 138.2 | I266: 143.2 | J266: 148.9 | K266: 150.3 | L266: 113.2 | M266: 159.8 | N266: 142.1 | O266: 161.8 | P266: 152.3 | Q266: 182.4 | R266: 154.7 | S266: 150 | T266: 154.1 | U266: 154.7 | V266: 144.9 | W266: 151.7 | X266: 158.2 | Y266: 141.4 | Z266: 153.2 | AA266: 161.8 | AB266: 151.2 | AC266: 151.7 | AD266: 152.7
A267: Urban | B267: 2020 | C267: June | D267: 152.7 | E267: 197 | F267: 154.6 | G267: 153.4 | H267: 132.9 | I267: 151.8 | J267: 171.2 | K267: 152 | L267: 116.3 | M267: 158.8 | N267: 135.6 | O267: 161.7 | P267: 157 | Q267: 186.7 | R267: 149.1 | S267: 136.6 | T267: 147.2 | U267: 154.7 | V267: 137.1 | W267: 140.4 | X267: 148.1 | Y267: 129.3 | Z267: 144.5 | AA267: 152.5 | AB267: 152.2 | AC267: 142 | AD267: 150.8
A268: Rural+Urban | B268: 2020 | C268: June | D268: 149.6 | E268: 192.7 | F268: 151.4 | G268: 153.3 | H268: 136.3 | I268: 147.2 | J268: 156.5 | K268: 150.9 | L268: 114.2 | M268: 159.5 | N268: 139.4 | O268: 161.8 | P268: 154 | Q268: 183.5 | R268: 152.5 | S268: 144.4 | T268: 151.4 | U268: 154.7 | V268: 141.9 | W268: 146.4 | X268: 154.4 | Y268: 135 | Z268: 148.3 | AA268: 156.4 | AB268: 151.6 | AC268: 147 | AD268: 151.8
A269: Rural | B269: 2020 | C269: July | D269: 148.2 | E269: 190.3 | F269: 149.4 | G269: 153.3 | H269: 138.2 | I269: 143.2 | J269: 148.9 | K269: 150.3 | L269: 113.2 | M269: 159.8 | N269: 142.1 | O269: 161.8 | P269: 152.3 | Q269: 182.4 | R269: 154.7 | S269: 150 | T269: 154.1 | U269: 154.7 | V269: 144.9 | W269: 151.7 | X269: 158.2 | Y269: 141.4 | Z269: 153.2 | AA269: 161.8 | AB269: 151.2 | AC269: 151.7 | AD269: 152.7
A270: Urban | B270: 2020 | C270: July | D270: 152.7 | E270: 197 | F270: 154.6 | G270: 153.4 | H270: 132.9 | I270: 151.8 | J270: 171.2 | K270: 152 | L270: 116.3 | M270: 158.8 | N270: 135.6 | O270: 161.7 | P270: 157 | Q270: 186.7 | R270: 149.1 | S270: 136.6 | T270: 147.2 | U270: 154.7 | V270: 137.1 | W270: 140.4 | X270: 148.1 | Y270: 129.3 | Z270: 144.5 | AA270: 152.5 | AB270: 152.2 | AC270: 142 | AD270: 150.8
A271: Rural+Urban | B271: 2020 | C271: July | D271: 149.6 | E271: 192.7 | F271: 151.4 | G271: 153.3 | H271: 136.3 | I271: 147.2 | J271: 156.5 | K271: 150.9 | L271: 114.2 | M271: 159.5 | N271: 139.4 | O271: 161.8 | P271: 154 | Q271: 183.5 | R271: 152.5 | S271: 144.4 | T271: 151.4 | U271: 154.7 | V271: 141.9 | W271: 146.4 | X271: 154.4 | Y271: 135 | Z271: 148.3 | AA271: 156.4 | AB271: 151.6 | AC271: 147 | AD271: 151.8
A272: Rural | B272: 2020 | C272: August | D272: 147.6 | E272: 187.2 | F272: 148.4 | G272: 153.3 | H272: 139.8 | I272: 146.9 | J272: 171 | K272: 149.9 | L272: 114.2 | M272: 160 | N272: 143.5 | O272: 161.5 | P272: 155.3 | Q272: 180.9 | R272: 155.1 | S272: 149.3 | T272: 154.3 | U272: 155.5 | V272: 145.8 | W272: 151.9 | X272: 158.8 | Y272: 143.6 | Z272: 152.2 | AA272: 162.7 | AB272: 153.6 | AC272: 153 | AD272: 154.7
A273: Urban | B273: 2020 | C273: August | D273: 151.6 | E273: 197.8 | F273: 154.5 | G273: 153.4 | H273: 133.4 | I273: 154.5 | J273: 191.9 | K273: 151.3 | L273: 116.8 | M273: 160 | N273: 136.5 | O273: 163.3 | P273: 159.9 | Q273: 187.2 | R273: 150 | S273: 135.2 | T273: 147.8 | U273: 155.5 | V273: 138.3 | W273: 144.5 | X273: 148.7 | Y273: 133.9 | Z273: 141.2 | AA273: 155.5 | AB273: 155.2 | AC273: 144.8 | AD273: 152.9
A274: Rural+Urban | B274: 2020 | C274: August | D274: 148.9 | E274: 190.9 | F274: 150.8 | G274: 153.3 | H274: 137.4 | I274: 150.4 | J274: 178.1 | K274: 150.4 | L274: 115.1 | M274: 160 | N274: 140.6 | O274: 162.3 | P274: 157 | Q274: 182.6 | R274: 153.1 | S274: 143.4 | T274: 151.7 | U274: 155.5 | V274: 143 | W274: 148.4 | X274: 155 | Y274: 138.5 | Z274: 146 | AA274: 158.5 | AB274: 154.3 | AC274: 149 | AD274: 153.9
A275: Rural | B275: 2020 | C275: September | D275: 146.9 | E275: 183.9 | F275: 149.5 | G275: 153.4 | H275: 140.4 | I275: 147 | J275: 178.8 | K275: 149.3 | L275: 115.1 | M275: 160 | N275: 145.4 | O275: 161.6 | P275: 156.1 | Q275: 182.9 | R275: 155.4 | S275: 149.9 | T275: 154.6 | U275: 156.3 | V275: 146.4 | W275: 151.6 | X275: 159.1 | Y275: 144.6 | Z275: 152.8 | AA275: 161.1 | AB275: 157.4 | AC275: 153.7 | AD275: 155.4
A276: Urban | B276: 2020 | C276: September | D276: 151.5 | E276: 193.1 | F276: 157.3 | G276: 153.9 | H276: 134.4 | I276: 155.4 | J276: 202 | K276: 150.8 | L276: 118.9 | M276: 160.9 | N276: 137.7 | O276: 164.4 | P276: 161.3 | Q276: 188.7 | R276: 150.2 | S276: 136.3 | T276: 148.1 | U276: 156.3 | V276: 137.2 | W276: 145.4 | X276: 150 | Y276: 135.1 | Z276: 141.8 | AA276: 154.9 | AB276: 159.8 | AC276: 146 | AD276: 154
A277: Rural+Urban | B277: 2020 | C277: September | D277: 148.4 | E277: 187.1 | F277: 152.5 | G277: 153.6 | H277: 138.2 | I277: 150.9 | J277: 186.7 | K277: 149.8 | L277: 116.4 | M277: 160.3 | N277: 142.2 | O277: 162.9 | P277: 158 | Q277: 184.4 | R277: 153.4 | S277: 144.3 | T277: 152 | U277: 156.3 | V277: 142.9 | W277: 148.7 | X277: 155.6 | Y277: 139.6 | Z277: 146.6 | AA277: 157.5 | AB277: 158.4 | AC277: 150 | AD277: 154.7
... A373: Rural+Urban | B373: 2023 | C373: May | D373: 173.7 | E373: 214.3 | F373: 173.2 | G373: 179.5 | H373: 170 | I373: 172.2 | J373: 161 | K373: 175.6 | L373: 122.7 | M373: 218 | N373: 173.4 | O373: 194.2 | P373: 179.1 | Q373: 201 | R373: 187.3 | S373: 179.7 | T373: 186.2 | U373: 175.6 | V373: 182.8 | W373: 175.2 | X373: 185.7 | Y373: 164.8 | Z373: 171.2 | AA373: 177.1 | AB373: 185.2 | AC373: 175.7 | AD373: 179.1

Sheet Category distribution
A1: Sector | E1: Sector
A2: Year | E2: Year
A3: Month | E3: Month
A4: Cereals and products
A5: Meat and fish
A6: Egg
A7: Milk and products
A8: Oils and fats | E8: FOOD
A9: Fruits
A10: Vegetables
A11: Pulses and products
A12: Sugar and Confectionery
A13: Spices
A14: Prepared meals, snacks, sweets etc.
A15: Food and beverages
A16: Non-alcoholic beverages
A17: Pan, tobacco and intoxicants
A18: Personal care and effects | E18: LUXURY
A19: Recreation and amusement
A21: Clothing
A22: Footwear | E22: CLOTHING
A23: Clothing and footwear
A24: Housing
A25: Household goods and services | E25: HOUSING
A26: Fuel and light | E26: FUEL AND LIGHT
A27: Transport and communication | D27: TRANSPORT AND
D28: COMMUNICATION
A29: Education | E29: EDUCATION
A30: Miscellaneous | E30: MISCELLANEOUS
A31: General index | E31: GENERAL INDEX
A32: Housing
A33: Fuel and light
A34: Transport and comm. | E34: Essential
A35: Education
A36: Miscellaneous

Sheet Data after buckets
A1: Sector | B1: Year | C1: Month | D1: Food | E1: Luxury | F1: Clothing | G1: Housing | H1: Fuel and Light | I1: Trans.& Commu. | J1: Education | K1: Miscel. | L1: Genral Index | M1: Essential
A2: Rural | B2: 2013 | C2: January | D2: =SUM('Data cleaning'!D2+'Data cleaning'!E2+'Data cleaning'!F2+'Data cleaning'!G2+'Data cleaning'!H2+'Data cleaning'!I2+'Data cleaning'!J2+'Data cleaning'!K2+'Data cleaning'!L2+'Data cleaning'!O2+'Data cleaning'!P2+'Data cleaning'!M2) -> 1266.9 | E2: =SUM('Data cleaning'!N2+'Data cleaning'!Q2+'Data cleaning'!AB2+'Data cleaning'!Z2) -> 418 | F2: =SUM('Data cleaning'!R2+'Data cleaning'!S2+'Data cleaning'!T2) -> 318.7 | G2: =SUM('Data cleaning'!U2+'Data cleaning'!W2) -> 205.1 | H2: 105.5 | I2: 103.3 | J2: 103.8 | K2: 104 | L2: 105.1 | M2: =SUM('Data cleaning'!U2+'Data cleaning'!V2+'Data cleaning'!Y2+'Data cleaning'!AC2) -> 413.1
A3: Urban | B3: 2013 | C3: January | D3: =SUM('Data cleaning'!D3+'Data cleaning'!E3+'Data cleaning'!F3+'Data cleaning'!G3+'Data cleaning'!H3+'Data cleaning'!I3+'Data cleaning'!J3+'Data cleaning'!K3+'Data cleaning'!L3+'Data cleaning'!O3+'Data cleaning'!P3+'Data cleaning'!M3) -> 1271.3 | E3: =SUM('Data cleaning'!N3+'Data cleaning'!Q3+'Data cleaning'!AB3+'Data cleaning'!Z3) -> 417.5 | F3: =SUM('Data cleaning'!R3+'Data cleaning'!S3+'Data cleaning'!T3) -> 316.7 | G3: =SUM('Data cleaning'!U3+'Data cleaning'!W3) -> 205.2 | H3: 105.4 | I3: 103.2 | J3: 103.5 | K3: 103.7 | L3: 104 | M3: =SUM('Data cleaning'!U3+'Data cleaning'!V3+'Data cleaning'!Y3+'Data cleaning'!AC3) -> 412.7
A4: Rural+Urban | B4: 2013 | C4: January | D4: =SUM('Data cleaning'!D4+'Data cleaning'!E4+'Data cleaning'!F4+'Data cleaning'!G4+'Data cleaning'!H4+'Data cleaning'!I4+'Data cleaning'!J4+'Data cleaning'!K4+'Data cleaning'!L4+'Data cleaning'!O4+'Data cleaning'!P4+'Data cleaning'!M4) -> 1268.4 | E4: =SUM('Data cleaning'!N4+'Data cleaning'!Q4+'Data cleaning'!AB4+'Data cleaning'!Z4) -> 417.6 | F4: =SUM('Data cleaning'!R4+'Data cleaning'!S4+'Data cleaning'!T4) -> 318 | G4: =SUM('Data cleaning'!U4+'Data cleaning'!W4) -> 205.2 | H4: 105.5 | I4: 103.2 | J4: 103.6 | K4: 103.9 | L4: 104.6 | M4: =SUM('Data cleaning'!U4+'Data cleaning'!V4+'Data cleaning'!Y4+'Data cleaning'!AC4) -> 413
A5: Rural | B5: 2013 | C5: February | D5: =SUM('Data cleaning'!D5+'Data cleaning'!E5+'Data cleaning'!F5+'Data cleaning'!G5+'Data cleaning'!H5+'Data cleaning'!I5+'Data cleaning'!J5+'Data cleaning'!K5+'Data cleaning'!L5+'Data cleaning'!O5+'Data cleaning'!P5+'Data cleaning'!M5) -> 1275.3 | E5: =SUM('Data cleaning'!N5+'Data cleaning'!Q5+'Data cleaning'!AB5+'Data cleaning'!Z5) -> 419.3 | F5: =SUM('Data cleaning'!R5+'Data cleaning'!S5+'Data cleaning'!T5) -> 320.4 | G5: =SUM('Data cleaning'!U5+'Data cleaning'!W5) -> 205.6 | H5: 106.2 | I5: 103.9 | J5: 104.1 | K5: 104.4 | L5: 105.8 | M5: =SUM('Data cleaning'!U5+'Data cleaning'!V5+'Data cleaning'!Y5+'Data cleaning'!AC5) -> 414.9
A6: Urban | B6: 2013 | C6: February | D6: =SUM('Data cleaning'!D6+'Data cleaning'!E6+'Data cleaning'!F6+'Data cleaning'!G6+'Data cleaning'!H6+'Data cleaning'!I6+'Data cleaning'!J6+'Data cleaning'!K6+'Data cleaning'!L6+'Data cleaning'!O6+'Data cleaning'!P6+'Data cleaning'!M6) -> 1284.6 | E6: =SUM('Data cleaning'!N6+'Data cleaning'!Q6+'Data cleaning'!AB6+'Data cleaning'!Z6) -> 419.6 | F6: =SUM('Data cleaning'!R6+'Data cleaning'!S6+'Data cleaning'!T6) -> 318.5 | G6: =SUM('Data cleaning'!U6+'Data cleaning'!W6) -> 205.7 | H6: 105.7 | I6: 104.4 | J6: 103.7 | K6: 104.3 | L6: 104.7 | M6: =SUM('Data cleaning'!U6+'Data cleaning'!V6+'Data cleaning'!Y6+'Data cleaning'!AC6) -> 414.9
A7: Rural+Urban | B7: 2013 | C7: February | D7: =SUM('Data cleaning'!D7+'Data cleaning'!E7+'Data cleaning'!F7+'Data cleaning'!G7+'Data cleaning'!H7+'Data cleaning'!I7+'Data cleaning'!J7+'Data cleaning'!K7+'Data cleaning'!L7+'Data cleaning'!O7+'Data cleaning'!P7+'Data cleaning'!M7) -> 1278.7 | E7: =SUM('Data cleaning'!N7+'Data cleaning'!Q7+'Data cleaning'!AB7+'Data cleaning'!Z7) -> 419.3 | F7: =SUM('Data cleaning'!R7+'Data cleaning'!S7+'Data cleaning'!T7) -> 319.7 | G7: =SUM('Data cleaning'!U7+'Data cleaning'!W7) -> 211.8 | H7: 106 | I7: 104.2 | J7: 103.9 | K7: 104.4 | L7: 105.3 | M7: =SUM('Data cleaning'!U7+'Data cleaning'!V7+'Data cleaning'!Y7+'Data cleaning'!AC7) -> 421.2
A8: Rural | B8: 2013 | C8: March | D8: =SUM('Data cleaning'!D8+'Data cleaning'!E8+'Data cleaning'!F8+'Data cleaning'!G8+'Data cleaning'!H8+'Data cleaning'!I8+'Data cleaning'!J8+'Data cleaning'!K8+'Data cleaning'!L8+'Data cleaning'!O8+'Data cleaning'!P8+'Data cleaning'!M8) -> 1276.6 | E8: =SUM('Data cleaning'!N8+'Data cleaning'!Q8+'Data cleaning'!AB8+'Data cleaning'!Z8) -> 420.4 | F8: =SUM('Data cleaning'!R8+'Data cleaning'!S8+'Data cleaning'!T8) -> 321.9 | G8: =SUM('Data cleaning'!U8+'Data cleaning'!W8) -> 206 | H8: 106.1 | I8: 104.6 | J8: 104.3 | K8: 104.6 | L8: 106 | M8: =SUM('Data cleaning'!U8+'Data cleaning'!V8+'Data cleaning'!Y8+'Data cleaning'!AC8) -> 415.7
A9: Urban | B9: 2013 | C9: March | D9: =SUM('Data cleaning'!D9+'Data cleaning'!E9+'Data cleaning'!F9+'Data cleaning'!G9+'Data cleaning'!H9+'Data cleaning'!I9+'Data cleaning'!J9+'Data cleaning'!K9+'Data cleaning'!L9+'Data cleaning'!O9+'Data cleaning'!P9+'Data cleaning'!M9) -> 1279.8 | E9: =SUM('Data cleaning'!N9+'Data cleaning'!Q9+'Data cleaning'!AB9+'Data cleaning'!Z9) -> 421.5 | F9: =SUM('Data cleaning'!R9+'Data cleaning'!S9+'Data cleaning'!T9) -> 320.2 | G9: =SUM('Data cleaning'!U9+'Data cleaning'!W9) -> 214.6 | H9: 106 | I9: 105.5 | J9: 103.8 | K9: 104.9 | L9: 105 | M9: =SUM('Data cleaning'!U9+'Data cleaning'!V9+'Data cleaning'!Y9+'Data cleaning'!AC9) -> 425.3
A10: Rural+Urban | B10: 2013 | C10: March | D10: =SUM('Data cleaning'!D10+'Data cleaning'!E10+'Data cleaning'!F10+'Data cleaning'!G10+'Data cleaning'!H10+'Data cleaning'!I10+'Data cleaning'!J10+'Data cleaning'!K10+'Data cleaning'!L10+'Data cleaning'!O10+'Data cleaning'!P10+'Data cleaning'!M10) -> 1277.8 | E10: =SUM('Data cleaning'!N10+'Data cleaning'!Q10+'Data cleaning'!AB10+'Data cleaning'!Z10) -> 420.8 | F10: =SUM('Data cleaning'!R10+'Data cleaning'!S10+'Data cleaning'!T10) -> 321.2 | G10: =SUM('Data cleaning'!U10+'Data cleaning'!W10) -> 215.3 | H10: 106.1 | I10: 105.1 | J10: 104 | K10: 104.7 | L10: 105.5 | M10: =SUM('Data cleaning'!U10+'Data cleaning'!V10+'Data cleaning'!Y10+'Data cleaning'!AC10) -> 425.6
A11: Rural | B11: 2013 | C11: April | D11: =SUM('Data cleaning'!D11+'Data cleaning'!E11+'Data cleaning'!F11+'Data cleaning'!G11+'Data cleaning'!H11+'Data cleaning'!I11+'Data cleaning'!J11+'Data cleaning'!K11+'Data cleaning'!L11+'Data cleaning'!O11+'Data cleaning'!P11+'Data cleaning'!M11) -> 1279.3 | E11: =SUM('Data cleaning'!N11+'Data cleaning'!Q11+'Data cleaning'!AB11+'Data cleaning'!Z11) -> 420.8 | F11: =SUM('Data cleaning'!R11+'Data cleaning'!S11+'Data cleaning'!T11) -> 323.5 | G11: =SUM('Data cleaning'!U11+'Data cleaning'!W11) -> 206.6 | H11: 106.5 | I11: 104.4 | J11: 104.8 | K11: 104.6 | L11: 106.4 | M11: =SUM('Data cleaning'!U11+'Data cleaning'!V11+'Data cleaning'!Y11+'Data cleaning'!AC11) -> 416
A12: Urban | B12: 2013 | C12: April | D12: =SUM('Data cleaning'!D12+'Data cleaning'!E12+'Data cleaning'!F12+'Data cleaning'!G12+'Data cleaning'!H12+'Data cleaning'!I12+'Data cleaning'!J12+'Data cleaning'!K12+'Data cleaning'!L12+'Data cleaning'!O12+'Data cleaning'!P12+'Data cleaning'!M12) -> 1289.5 | E12: =SUM('Data cleaning'!N12+'Data cleaning'!Q12+'Data cleaning'!AB12+'Data cleaning'!Z12) -> 423.9 | F12: =SUM('Data cleaning'!R12+'Data cleaning'!S12+'Data cleaning'!T12) -> 322 | G12: =SUM('Data cleaning'!U12+'Data cleaning'!W12) -> 207 | H12: 106.4 | I12: 105 | J12: 105.2 | K12: 105.1 | L12: 105.7 | M12: =SUM('Data cleaning'!U12+'Data cleaning'!V12+'Data cleaning'!Y12+'Data cleaning'!AC12) -> 417
A13: Rural+Urban | B13: 2013 | C13: April | D13: =SUM('Data cleaning'!D13+'Data cleaning'!E13+'Data cleaning'!F13+'Data cleaning'!G13+'Data cleaning'!H13+'Data cleaning'!I13+'Data cleaning'!J13+'Data cleaning'!K13+'Data cleaning'!L13+'Data cleaning'!O13+'Data cleaning'!P13+'Data cleaning'!M13) -> 1283 | E13: =SUM('Data cleaning'!N13+'Data cleaning'!Q13+'Data cleaning'!AB13+'Data cleaning'!Z13) -> 421.8 | F13: =SUM('Data cleaning'!R13+'Data cleaning'!S13+'Data cleaning'!T13) -> 322.9 | G13: =SUM('Data cleaning'!U13+'Data cleaning'!W13) -> 206.8 | H13: 106.5 | I13: 104.7 | J13: 105 | K13: 104.8 | L13: 106.1 | M13: =SUM('Data cleaning'!U13+'Data cleaning'!V13+'Data cleaning'!Y13+'Data cleaning'!AC13) -> 416.5
... A259: Rural+Urban | B259: 2020 | C259: March | D259: =SUM('Data cleaning'!D259+'Data cleaning'!E259+'Data cleaning'!F259+'Data cleaning'!G259+'Data cleaning'!H259+'Data cleaning'!I259+'Data cleaning'!J259+'Data cleaning'!K259+'Data cleaning'!L259+'Data cleaning'!O259+'Data cleaning'!P259+'Data cleaning'!M259) -> 1758.7 | E259: =SUM('Data cleaning'!N259+'Data cleaning'!Q259+'Data cleaning'!AB259+'Data cleaning'!Z259) -> 596.8 | F259: =SUM('Data cleaning'!R259+'Data cleaning'!S259+'Data cleaning'!T259) -> 442.9 | G259: =SUM('Data cleaning'!U259+'Data cleaning'!W259) -> 300.9 | H259: 148.9 | I259: 129.9 | J259: 156.1 | K259: 143.8 | L259: 148.6 | M259: =SUM('Data cleaning'!U259+'Data cleaning'!V259+'Data cleaning'!Y259+'Data cleaning'!AC259) -> 577.1
A260: Rural | B260: 2020 | C260: April | D260: =SUM('Data cleaning'!D260+'Data cleaning'!E260+'Data cleaning'!F260+'Data cleaning'!G260+'Data cleaning'!H260+'Data cleaning'!I260+'Data cleaning'!J260+'Data cleaning'!K260+'Data cleaning'!L260+'Data cleaning'!O260+'Data cleaning'!P260+'Data cleaning'!M260) -> 1802.1 | E260: =SUM('Data cleaning'!N260+'Data cleaning'!Q260+'Data cleaning'!AB260+'Data cleaning'!Z260) -> 602.93333 | F260: =SUM('Data cleaning'!R260+'Data cleaning'!S260+'Data cleaning'!T260) -> 452.86667 | G260: =SUM('Data cleaning'!U260+'Data cleaning'!W260) -> 307.26667 | H260: 148.4 | I260: =AVERAGE(I261:I269) -> 140.04259 | J260: =AVERAGE(J261:J265) -> 161.1016 | K260: =AVERAGE(K261:K265) -> 153.4468 | L260: =AVERAGE(L261:L265) -> 157.9432 | M260: =SUM('Data cleaning'!U260+'Data cleaning'!V260+'Data cleaning'!Y260+'Data cleaning'!AC260) -> 588.4
A261: Urban | B261: 2020 | C261: April | D261: =SUM('Data cleaning'!D261+'Data cleaning'!E261+'Data cleaning'!F261+'Data cleaning'!G261+'Data cleaning'!H261+'Data cleaning'!I261+'Data cleaning'!J261+'Data cleaning'!K261+'Data cleaning'!L261+'Data cleaning'!O261+'Data cleaning'!P261+'Data cleaning'!M261) -> 1829.6333 | E261: =SUM('Data cleaning'!N261+'Data cleaning'!Q261+'Data cleaning'!AB261+'Data cleaning'!Z261) -> 566.8 | F261: =SUM('Data cleaning'!R261+'Data cleaning'!S261+'Data cleaning'!T261) -> 426.06667 | G261: =SUM('Data cleaning'!U261+'Data cleaning'!W261) -> 296.03333 | H261: 137.1 | I261: =AVERAGE(I262:I268) -> 139.87292 | J261: =AVERAGE(J262:J266) -> 161.218 | K261: =AVERAGE(K262:K266) -> 153.15567 | L261: =AVERAGE(L262:L266) -> 157.06933 | M261: =SUM('Data cleaning'!U261+'Data cleaning'!V261+'Data cleaning'!Y261+'Data cleaning'!AC261) -> 556.5
A262: Rural+Urban | B262: 2020 | C262: April | D262: =SUM('Data cleaning'!D262+'Data cleaning'!E262+'Data cleaning'!F262+'Data cleaning'!G262+'Data cleaning'!H262+'Data cleaning'!I262+'Data cleaning'!J262+'Data cleaning'!K262+'Data cleaning'!L262+'Data cleaning'!O262+'Data cleaning'!P262+'Data cleaning'!M262) -> 1812.3 | E262: =SUM('Data cleaning'!N262+'Data cleaning'!Q262+'Data cleaning'!AB262+'Data cleaning'!Z262) -> 593.83333 | F262: =SUM('Data cleaning'!R262+'Data cleaning'!S262+'Data cleaning'!T262) -> 442.03333 | G262: =SUM('Data cleaning'!U262+'Data cleaning'!W262) -> 301.93333 | H262: 144.1 | I262: =AVERAGE(I263:I268) -> 139.87292 | J262: =AVERAGE(J263:J267) -> 159.765 | K262: =AVERAGE(K263:K267) -> 151.29639 | L262: =AVERAGE(L263:L267) -> 156.02444 | M262: =SUM('Data cleaning'!U262+'Data cleaning'!V262+'Data cleaning'!Y262+'Data cleaning'!AC262) -> 573.66667
A263: Rural | B263: 2020 | C263: May | D263: =SUM('Data cleaning'!D263+'Data cleaning'!E263+'Data cleaning'!F263+'Data cleaning'!G263+'Data cleaning'!H263+'Data cleaning'!I263+'Data cleaning'!J263+'Data cleaning'!K263+'Data cleaning'!L263+'Data cleaning'!O263+'Data cleaning'!P263+'Data cleaning'!M263) -> 1780.375 | E263: =SUM('Data cleaning'!N263+'Data cleaning'!Q263+'Data cleaning'!AB263+'Data cleaning'!Z263) -> 603.50833 | F263: =SUM('Data cleaning'!R263+'Data cleaning'!S263+'Data cleaning'!T263) -> 452.86667 | G263: =SUM('Data cleaning'!U263+'Data cleaning'!W263) -> 306.36667 | H263: =AVERAGE(H264:H268) -> 146.93667 | I263: =AVERAGE(I264:I268) -> 139.87292 | J263: =AVERAGE(J264:J268) -> 159.20417 | K263: =AVERAGE(K264:K268) -> 150.58032 | L263: =AVERAGE(L264:L268) -> 155.32037 | M263: =SUM('Data cleaning'!U263+'Data cleaning'!V263+'Data cleaning'!Y263+'Data cleaning'!AC263) -> 590.225
A264: Urban | B264: 2020 | C264: May | D264: =SUM('Data cleaning'!D264+'Data cleaning'!E264+'Data cleaning'!F264+'Data cleaning'!G264+'Data cleaning'!H264+'Data cleaning'!I264+'Data cleaning'!J264+'Data cleaning'!K264+'Data cleaning'!L264+'Data cleaning'!O264+'Data cleaning'!P264+'Data cleaning'!M264) -> 1798.9083 | E264: =SUM('Data cleaning'!N264+'Data cleaning'!Q264+'Data cleaning'!AB264+'Data cleaning'!Z264) -> 580.275 | F264: =SUM('Data cleaning'!R264+'Data cleaning'!S264+'Data cleaning'!T264) -> 426.06667 | G264: =SUM('Data cleaning'!U264+'Data cleaning'!W264) -> 295.13333 | H264: =AVERAGE(H265:H269) -> 146.59722 | I264: =AVERAGE(I265:I268) -> 139.87292 | J264: =AVERAGE(J265:J268) -> 159.20417 | K264: =AVERAGE(K265:K268) -> 150.58032 | L264: =AVERAGE(L265:L268) -> 155.32037 | M264: =SUM('Data cleaning'!U264+'Data cleaning'!V264+'Data cleaning'!Y264+'Data cleaning'!AC264) -> 556.625
A265: Rural+Urban | B265: 2020 | C265: May | D265: =SUM('Data cleaning'!D265+'Data cleaning'!E265+'Data cleaning'!F265+'Data cleaning'!G265+'Data cleaning'!H265+'Data cleaning'!I265+'Data cleaning'!J265+'Data cleaning'!K265+'Data cleaning'!L265+'Data cleaning'!O265+'Data cleaning'!P265+'Data cleaning'!M265) -> 1787.6 | E265: =SUM('Data cleaning'!N265+'Data cleaning'!Q265+'Data cleaning'!AB265+'Data cleaning'!Z265) -> 593.55833 | F265: =SUM('Data cleaning'!R265+'Data cleaning'!S265+'Data cleaning'!T265) -> 442.03333 | G265: =SUM('Data cleaning'!U265+'Data cleaning'!W265) -> 301.03333 | H265: =AVERAGE(H266:H373) -> 164.18611 | I265: =AVERAGE(I266:I373) -> 153.79167 | J265: =AVERAGE(J266:J373) -> 166.11667 | K265: =AVERAGE(K266:K373) -> 161.6213 | L265: =AVERAGE(L266:L373) -> 165.98148 | M265: =SUM('Data cleaning'!U265+'Data cleaning'!V265+'Data cleaning'!Y265+'Data cleaning'!AC265) -> 574.86667
A266: Rural | B266: 2020 | C266: June | D266: =SUM('Data cleaning'!D266+'Data cleaning'!E266+'Data cleaning'!F266+'Data cleaning'!G266+'Data cleaning'!H266+'Data cleaning'!I266+'Data cleaning'!J266+'Data cleaning'!K266+'Data cleaning'!L266+'Data cleaning'!O266+'Data cleaning'!P266+'Data cleaning'!M266) -> 1808.9 | E266: =SUM('Data cleaning'!N266+'Data cleaning'!Q266+'Data cleaning'!AB266+'Data cleaning'!Z266) -> 628.9 | F266: =SUM('Data cleaning'!R266+'Data cleaning'!S266+'Data cleaning'!T266) -> 458.8 | G266: =SUM('Data cleaning'!U266+'Data cleaning'!W266) -> 306.4 | H266: 144.9 | I266: 141.4 | J266: 161.8 | K266: 151.7 | L266: 152.7 | M266: =SUM('Data cleaning'!U266+'Data cleaning'!V266+'Data cleaning'!Y266+'Data cleaning'!AC266) -> 592.7
A267: Urban | B267: 2020 | C267: June | D267: =SUM('Data cleaning'!D267+'Data cleaning'!E267+'Data cleaning'!F267+'Data cleaning'!G267+'Data cleaning'!H267+'Data cleaning'!I267+'Data cleaning'!J267+'Data cleaning'!K267+'Data cleaning'!L267+'Data cleaning'!O267+'Data cleaning'!P267+'Data cleaning'!M267) -> 1859.4 | E267: =SUM('Data cleaning'!N267+'Data cleaning'!Q267+'Data cleaning'!AB267+'Data cleaning'!Z267) -> 619 | F267: =SUM('Data cleaning'!R267+'Data cleaning'!S267+'Data cleaning'!T267) -> 432.9 | G267: =SUM('Data cleaning'!U267+'Data cleaning'!W267) -> 295.1 | H267: 137.1 | I267: 129.3 | J267: 152.5 | K267: 142 | L267: 150.8 | M267: =SUM('Data cleaning'!U267+'Data cleaning'!V267+'Data cleaning'!Y267+'Data cleaning'!AC267) -> 563.1
A268: Rural+Urban | B268: 2020 | C268: June | D268: =SUM('Data cleaning'!D268+'Data cleaning'!E268+'Data cleaning'!F268+'Data cleaning'!G268+'Data cleaning'!H268+'Data cleaning'!I268+'Data cleaning'!J268+'Data cleaning'!K268+'Data cleaning'!L268+'Data cleaning'!O268+'Data cleaning'!P268+'Data cleaning'!M268) -> 1827.4 | E268: =SUM('Data cleaning'!N268+'Data cleaning'!Q268+'Data cleaning'!AB268+'Data cleaning'!Z268) -> 622.8 | F268: =SUM('Data cleaning'!R268+'Data cleaning'!S268+'Data cleaning'!T268) -> 448.3 | G268: =SUM('Data cleaning'!U268+'Data cleaning'!W268) -> 301.1 | H268: 141.9 | I268: 135 | J268: 156.4 | K268: 147 | L268: 151.8 | M268: =SUM('Data cleaning'!U268+'Data cleaning'!V268+'Data cleaning'!Y268+'Data cleaning'!AC268) -> 578.6
A269: Rural | B269: 2020 | C269: July | D269: =SUM('Data cleaning'!D269+'Data cleaning'!E269+'Data cleaning'!F269+'Data cleaning'!G269+'Data cleaning'!H269+'Data cleaning'!I269+'Data cleaning'!J269+'Data cleaning'!K269+'Data cleaning'!L269+'Data cleaning'!O269+'Data cleaning'!P269+'Data cleaning'!M269) -> 1808.9 | E269: =SUM('Data cleaning'!N269+'Data cleaning'!Q269+'Data cleaning'!AB269+'Data cleaning'!Z269) -> 628.9 | F269: =SUM('Data cleaning'!R269+'Data cleaning'!S269+'Data cleaning'!T269) -> 458.8 | G269: =SUM('Data cleaning'!U269+'Data cleaning'!W269) -> 306.4 | H269: 144.9 | I269: 141.4 | J269: 161.8 | K269: 151.7 | L269: 152.7 | M269: =SUM('Data cleaning'!U269+'Data cleaning'!V269+'Data cleaning'!Y269+'Data cleaning'!AC269) -> 592.7
A270: Urban | B270: 2020 | C270: July | D270: =SUM('Data cleaning'!D270+'Data cleaning'!E270+'Data cleaning'!F270+'Data cleaning'!G270+'Data cleaning'!H270+'Data cleaning'!I270+'Data cleaning'!J270+'Data cleaning'!K270+'Data cleaning'!L270+'Data cleaning'!O270+'Data cleaning'!P270+'Data cleaning'!M270) -> 1859.4 | E270: =SUM('Data cleaning'!N270+'Data cleaning'!Q270+'Data cleaning'!AB270+'Data cleaning'!Z270) -> 619 | F270: =SUM('Data cleaning'!R270+'Data cleaning'!S270+'Data cleaning'!T270) -> 432.9 | G270: =SUM('Data cleaning'!U270+'Data cleaning'!W270) -> 295.1 | H270: 137.1 | I270: 129.3 | J270: 152.5 | K270: 142 | L270: 150.8 | M270: =SUM('Data cleaning'!U270+'Data cleaning'!V270+'Data cleaning'!Y270+'Data cleaning'!AC270) -> 563.1
A271: Rural+Urban | B271: 2020 | C271: July | D271: =SUM('Data cleaning'!D271+'Data cleaning'!E271+'Data cleaning'!F271+'Data cleaning'!G271+'Data cleaning'!H271+'Data cleaning'!I271+'Data cleaning'!J271+'Data cleaning'!K271+'Data cleaning'!L271+'Data cleaning'!O271+'Data cleaning'!P271+'Data cleaning'!M271) -> 1827.4 | E271: =SUM('Data cleaning'!N271+'Data cleaning'!Q271+'Data cleaning'!AB271+'Data cleaning'!Z271) -> 622.8 | F271: =SUM('Data cleaning'!R271+'Data cleaning'!S271+'Data cleaning'!T271) -> 448.3 | G271: =SUM('Data cleaning'!U271+'Data cleaning'!W271) -> 301.1 | H271: 141.9 | I271: 135 | J271: 156.4 | K271: 147 | L271: 151.8 | M271: =SUM('Data cleaning'!U271+'Data cleaning'!V271+'Data cleaning'!Y271+'Data cleaning'!AC271) -> 578.6
A272: Rural | B272: 2020 | C272: August | D272: =SUM('Data cleaning'!D272+'Data cleaning'!E272+'Data cleaning'!F272+'Data cleaning'!G272+'Data cleaning'!H272+'Data cleaning'!I272+'Data cleaning'!J272+'Data cleaning'!K272+'Data cleaning'!L272+'Data cleaning'!O272+'Data cleaning'!P272+'Data cleaning'!M272) -> 1835.1 | E272: =SUM('Data cleaning'!N272+'Data cleaning'!Q272+'Data cleaning'!AB272+'Data cleaning'!Z272) -> 630.2 | F272: =SUM('Data cleaning'!R272+'Data cleaning'!S272+'Data cleaning'!T272) -> 458.7 | G272: =SUM('Data cleaning'!U272+'Data cleaning'!W272) -> 307.4 | H272: 145.8 | I272: 143.6 | J272: 162.7 | K272: 153 | L272: 154.7 | M272: =SUM('Data cleaning'!U272+'Data cleaning'!V272+'Data cleaning'!Y272+'Data cleaning'!AC272) -> 597.9
A273: Urban | B273: 2020 | C273: August | D273: =SUM('Data cleaning'!D273+'Data cleaning'!E273+'Data cleaning'!F273+'Data cleaning'!G273+'Data cleaning'!H273+'Data cleaning'!I273+'Data cleaning'!J273+'Data cleaning'!K273+'Data cleaning'!L273+'Data cleaning'!O273+'Data cleaning'!P273+'Data cleaning'!M273) -> 1888.4 | E273: =SUM('Data cleaning'!N273+'Data cleaning'!Q273+'Data cleaning'!AB273+'Data cleaning'!Z273) -> 620.1 | F273: =SUM('Data cleaning'!R273+'Data cleaning'!S273+'Data cleaning'!T273) -> 433 | G273: =SUM('Data cleaning'!U273+'Data cleaning'!W273) -> 300 | H273: 138.3 | I273: 133.9 | J273: 155.5 | K273: 144.8 | L273: 152.9 | M273: =SUM('Data cleaning'!U273+'Data cleaning'!V273+'Data cleaning'!Y273+'Data cleaning'!AC273) -> 572.5
A274: Rural+Urban | B274: 2020 | C274: August | D274: =SUM('Data cleaning'!D274+'Data cleaning'!E274+'Data cleaning'!F274+'Data cleaning'!G274+'Data cleaning'!H274+'Data cleaning'!I274+'Data cleaning'!J274+'Data cleaning'!K274+'Data cleaning'!L274+'Data cleaning'!O274+'Data cleaning'!P274+'Data cleaning'!M274) -> 1854.6 | E274: =SUM('Data cleaning'!N274+'Data cleaning'!Q274+'Data cleaning'!AB274+'Data cleaning'!Z274) -> 623.5 | F274: =SUM('Data cleaning'!R274+'Data cleaning'!S274+'Data cleaning'!T274) -> 448.2 | G274: =SUM('Data cleaning'!U274+'Data cleaning'!W274) -> 303.9 | H274: 143 | I274: 138.5 | J274: 158.5 | K274: 149 | L274: 153.9 | M274: =SUM('Data cleaning'!U274+'Data cleaning'!V274+'Data cleaning'!Y274+'Data cleaning'!AC274) -> 586
A275: Rural | B275: 2020 | C275: September | D275: =SUM('Data cleaning'!D275+'Data cleaning'!E275+'Data cleaning'!F275+'Data cleaning'!G275+'Data cleaning'!H275+'Data cleaning'!I275+'Data cleaning'!J275+'Data cleaning'!K275+'Data cleaning'!L275+'Data cleaning'!O275+'Data cleaning'!P275+'Data cleaning'!M275) -> 1842 | E275: =SUM('Data cleaning'!N275+'Data cleaning'!Q275+'Data cleaning'!AB275+'Data cleaning'!Z275) -> 638.5 | F275: =SUM('Data cleaning'!R275+'Data cleaning'!S275+'Data cleaning'!T275) -> 459.9 | G275: =SUM('Data cleaning'!U275+'Data cleaning'!W275) -> 307.9 | H275: 146.4 | I275: 144.6 | J275: 161.1 | K275: 153.7 | L275: 155.4 | M275: =SUM('Data cleaning'!U275+'Data cleaning'!V275+'Data cleaning'!Y275+'Data cleaning'!AC275) -> 601
A276: Urban | B276: 2020 | C276: September | D276: =SUM('Data cleaning'!D276+'Data cleaning'!E276+'Data cleaning'!F276+'Data cleaning'!G276+'Data cleaning'!H276+'Data cleaning'!I276+'Data cleaning'!J276+'Data cleaning'!K276+'Data cleaning'!L276+'Data cleaning'!O276+'Data cleaning'!P276+'Data cleaning'!M276) -> 1903.9 | E276: =SUM('Data cleaning'!N276+'Data cleaning'!Q276+'Data cleaning'!AB276+'Data cleaning'!Z276) -> 628 | F276: =SUM('Data cleaning'!R276+'Data cleaning'!S276+'Data cleaning'!T276) -> 434.6 | G276: =SUM('Data cleaning'!U276+'Data cleaning'!W276) -> 301.7 | H276: 137.2 | I276: 135.1 | J276: 154.9 | K276: 146 | L276: 154 | M276: =SUM('Data cleaning'!U276+'Data cleaning'!V276+'Data cleaning'!Y276+'Data cleaning'!AC276) -> 574.6
A277: Rural+Urban | B277: 2020 | C277: September | D277: =SUM('Data cleaning'!D277+'Data cleaning'!E277+'Data cleaning'!F277+'Data cleaning'!G277+'Data cleaning'!H277+'Data cleaning'!I277+'Data cleaning'!J277+'Data cleaning'!K277+'Data cleaning'!L277+'Data cleaning'!O277+'Data cleaning'!P277+'Data cleaning'!M277) -> 1864.8 | E277: =SUM('Data cleaning'!N277+'Data cleaning'!Q277+'Data cleaning'!AB277+'Data cleaning'!Z277) -> 631.6 | F277: =SUM('Data cleaning'!R277+'Data cleaning'!S277+'Data cleaning'!T277) -> 449.7 | G277: =SUM('Data cleaning'!U277+'Data cleaning'!W277) -> 305 | H277: 142.9 | I277: 139.6 | J277: 157.5 | K277: 150 | L277: 154.7 | M277: =SUM('Data cleaning'!U277+'Data cleaning'!V277+'Data cleaning'!Y277+'Data cleaning'!AC277) -> 588.8
... A373: Rural+Urban | B373: 2023 | C373: May | D373: =SUM('Data cleaning'!D373+'Data cleaning'!E373+'Data cleaning'!F373+'Data cleaning'!G373+'Data cleaning'!H373+'Data cleaning'!I373+'Data cleaning'!J373+'Data cleaning'!K373+'Data cleaning'!L373+'Data cleaning'!O373+'Data cleaning'!P373+'Data cleaning'!M373) -> 2133.5 | E373: =SUM('Data cleaning'!N373+'Data cleaning'!Q373+'Data cleaning'!AB373+'Data cleaning'!Z373) -> 730.8 | F373: =SUM('Data cleaning'!R373+'Data cleaning'!S373+'Data cleaning'!T373) -> 553.2 | G373: =SUM('Data cleaning'!U373+'Data cleaning'!W373) -> 350.8 | H373: 182.8 | I373: 164.8 | J373: 177.1 | K373: 175.7 | L373: 179.1 | M373: =SUM('Data cleaning'!U373+'Data cleaning'!V373+'Data cleaning'!Y373+'Data cleaning'!AC373) -> 698.9

Sheet Q.1
A1: Q.1 Based on the latest month's data,identify the contribution of different broader categories towards the CPI basket. Broader categories can be created by combining similar categories into one bucket .
A3: . Which broader category has the highest contribution has towards CPI calculation
A5: . Contribution is Calculated by evaluating the underlying index values for broader category and should add to 100% when contribution from different broader categories are added.
G7: Latest month's data -May 2023
A10: Sector | B10: Rural | C10: % Contribution
A11: Food | B11: 2112 | C11: =B11/B21 -> 0.39302529 | O11: Broader Category Food Has
A12: Luxury | B12: 737.3 | C12: =B12/B21 -> 0.13720528 | O12: Highest Contribution
A13: Clothing | B13: 569.9 | C13: =B13/B21 -> 0.10605356
A14: Housing | B14: 355.4 | C14: =B14/B21 -> 0.066136926
A15: Fuel and Light | B15: 182.5 | C15: =B15/B21 -> 0.033961702
A16: Trans and commu. | B16: 169.7 | C16: =B16/B21 -> 0.031579731
A17: Education | B17: 180.3 | C17: =B17/B21 -> 0.033552301
A18: Misc. | B18: 179.5 | C18: =B18/B21 -> 0.033403428
A19: Genral in. | B19: 179.8 | C19: =B19/B21 -> 0.033459255
A20: Essential | B20: 707.3 | C20: =B20/B21 -> 0.13162253
A21: Total | B21: =SUM(B11:B20) -> 5373.7 | C21: 1
A26: Sector | B26: Urban | C26: % Contribution
A27: Food | B27: 2169.2 | C27: =B27/B37 -> 0.40713977
A28: Luxury | B28: 724.9 | C28: =B28/B37 -> 0.13605736
A29: Clothing | B29: 528.7 | C29: =B29/B37 -> 0.099232343 | O29: Broader Category Food Has
A30: Housing | B30: 345.7 | C30: =B30/B37 -> 0.064884851 | O30: Highest Contribution
A31: Fuel and Light | B31: 183.4 | C31: =B31/B37 -> 0.034422568
A32: Trans and commu. | B32: 160.4 | C32: =B32/B37 -> 0.03010567
A33: Education | B33: 174.8 | C33: =B33/B37 -> 0.032808424
A34: Misc. | B34: 171.6 | C34: =B34/B37 -> 0.032207812
A35: Genral in. | B35: 178.2 | C35: =B35/B37 -> 0.033446574
A36: Essential | B36: 691 | C36: =B36/B37 -> 0.12969463
A37: Total | B37: =SUM(B27:B36) -> 5327.9 | C37: 1
A45: Sector | B45: Rural+Urban | C45: % Contribution
A46: Food | B46: 2133.5 | C46: =B46/B56 -> 0.39903118
A47: Luxury | B47: 730.8 | C47: =B47/B56 -> 0.13668244
A48: Clothing | B48: 553.2 | C48: =B48/B56 -> 0.10346569
A49: Housing | B49: 350.8 | C49: =B49/B56 -> 0.065610564
A50: Fuel and Light | B50: 182.8 | C50: =B50/B56 -> 0.034189313 | O50: Broader Category Food Has
A51: Trans and commu. | B51: 164.8 | C51: =B51/B56 -> 0.03082275 | O51: Highest Contribution
A52: Education | B52: 177.1 | C52: =B52/B56 -> 0.033123235
A53: Misc. | B53: 175.7 | C53: =B53/B56 -> 0.032861391
A54: Genral in. | B54: 179.1 | C54: =B54/B56 -> 0.033497297
A55: Essential | B55: 698.9 | C55: =B55/B56 -> 0.13071614
A56: Total | B56: =SUM(B46:B55) -> 5346.7 | C56: 1

Sheet Q.2
A1: Q.2 A trend of Y-O-Y increase in CPI (RURAL+URBAN) inflation starting 2017 for the entire basket of product combine.
A3: . Create a graph depicting the growth rat Y-O-Y and identify the year with highest inflation rate.
A4: . Hightlight the reason why the year has the highest inflation.
B9: Sector | C9: (All)
A11: Sector | B11: Year | C11: Average of General index | D11: Inflation | G11: Year | H11: Inflation
A12: Rural+Urban | B12: 2013 | C12: 110.01389 | G12: 2013
